Workbook

Sheet Master Listings
A1: Investment Name | B1: Sponsor | C1: Structure | D1: Status | E1: Total Offering | F1: Equity | G1: Debt | H1: In-Place LTV | I1: Available Equity | J1: Last Updated | K1: Available Percentage | L1: Property Type | M1: Location | N1: Location (Use) | O1: Total Load | P1: Strategy | Q1: 721 Exchange Exit | R1: Estimated Hold Period | S1: Description | T1: Highlight 1 | U1: Highlight 2 | V1: Highlight 3 | W1: Highlight 4 | X1: Highlight 5 | Y1: Pros | Z1: Cons | AA1: Insights | AB1: Y1 | AC1: Y2 | AD1: Y3 | AE1: Y4 | AF1: Y5 | AG1: Y6 | AH1: Y7 | AI1: Y8 | AJ1: Y9 | AK1: Y10 | AL1: Average Yield | AM1: Tax-Adj. Yield | AN1: Cap Rate Equivalent | AO1: Lender | AP1: Interest Rate | AQ1: Loan Term | AR1: I/O Period | AS1: Amortization | AT1: Y1 DSCR | AU1: Property Address | AV1: Property Photo Link | AW1: DD Folder Link | AX1: Minimum Investment | AY1: Photo Link Use | AZ1: Tax Adjusted Yield (Use) | BA1: Tax Adj Label | BB1: DD Label | BC1: URL | BD1: Sponsor URL | BE1: Prop Type URL | BF1: Sponsor Button Text | BG1: Property Type Button Text | BH1: Sponsor Founded | BI1: Sponsor Description | BJ1: Sponsor AUM | BK1: Full-Cycle Count | BL1: Sponsor AAR | BM1: Sponsor AEM | BN1: Sponsor Hold | BO1: Sponsor Success | BP1: Sponsor Image | BQ1: BM: Avg. Income - Deal | BR1: BM: Avg. Income - MKT | BS1: BM: Avg. Income - Interpret | BT1: BM: Growth - Deal | BU1: BM: Growth- MKT | BV1: BM: Growth - Interpret | BW1: BM: Peak - Deal | BX1: BM: Peak- MKT | BY1: BM: Peak - Interpret | BZ1: List Description | CA1: Investment Description Copy/Paste
A2: AEI Healthcare Portfolio VII DST | B2: AEI Capital Corporation | C2: Delaware Statutory Trust (DST) | D2: Available | E2: 50500000 | F2: 50500000 | G2: 0 | H2: 0.00% LTV | I2: 25680857 | J2: 46169 | K2: =(I2/F2) -> 0.50853182 | L2: Healthcare | M2: AZ, TX, CT | N2: =IFERROR(__xludf.DUMMYFUNCTION("TEXTJOIN("", "", TRUE, SORT(TRANSPOSE(SPLIT(M2, "", ""))))"),"AZ, CT, TX") -> AZ, CT, TX | O2: 9.12% | P2: Core | Q2: Optional | R2: 10 years | S2: Three purpose-built, single-tenant outpatient medical office assets held debt-free in a DST: HonorHealth Complete Care (12,000 SF, Surprise AZ, Phoenix MSA, lease to 2042), Texas Children's Pavilion for Women (12,642 SF, Cedar Park/Austin TX, co-located one block from the tenant's own hospital campus, lease to 2038), and a United Healthcare/ProHealth Physicians clinic (26,547 SF on 6.40 ac, Bristol CT, lease to 2037). Submarkets are infill/Sun Belt growth corridors with strong daytime traffic and household incomes ($78k-$125k) and constrained MOB supply (~6.9% national availability). Thesis is durable, escalating net-lease income from investment-grade-equivalent healthcare credit, underpinned by secular outpatient-care migration and aging demographics. Operating strategy is passive triple-net ownership through an affiliated master tenant, with insurance fully tenant-reimbursed and de minimis trust-level expense; income growth is driven entirely by contractual 2.0%-2.5% escalators. | T2: The portfolio exhibits a credit barbell. Texas Children's Hospital (AA-/Fitch) and the UnitedHealth Group parent (AA-/Fitch, A/AM Best) supply investment-grade-equivalent corporate backing, while HonorHealth (A+/Fitch) is a single-state Arizona nonprofit system. Income is disproportionately weighted to Bristol, whose ~$1.15M gross rent is roughly 44% of in-place rent, concentrating cash flow in a single asset and a single tenant whose parent's Fitch outlook was revised to negative in July 2025 - a trajectory the static AA- marketing presentation omits. | U2: Weighted average remaining lease term is 13.62 years across staggered expirations (Surprise 2042, Austin 2038, Bristol 2037). Duration is asymmetric: the long-dated HonorHealth lease carries the lowest escalator (2.0%), while the largest asset (Bristol) escalates 2.5% only through year 9 and then steps flat, capping income growth on the portfolio's biggest rent stream precisely as the projected disposition window approaches. | V2: Real estate quality is high and recently delivered (2022-2024 vintage), purpose-built for outpatient use. The Austin asset's co-location one block from Texas Children's own hospital campus creates a mission-critical referral linkage that raises renewal probability and tenant switching costs; the Surprise asset is the sole urgent care within a 3.5-mile radius in a high-traffic retail corridor (71,024 VPD). These siting characteristics function as soft barriers to entry that support re-leasing economics. | W2: The debt-free capital structure removes refinancing, maturity, rate-cap, and foreclosure risk entirely, and eliminates the equal-or-greater-debt replacement requirement for 1031 investors averse to boot-offsetting leverage. The structural cost is the absence of positive financial leverage, which mechanically caps levered IRR and is the primary reason the 5.00% going-in distribution sits below comparable leveraged net-lease DSTs. | X2: The triple-net structure with tenant-reimbursed insurance and ~$1,400/year trust-level property expense insulates distributable cash from operating inflation. The qualifier is capital responsibility: the Trust retains certain capex obligations funded only from a modest reserve that declines from $371,000 to ~$67,764 by 2035, drawn down immediately by a $221,000 Connecticut transfer-tax charge in year 1, leaving limited capacity for unbudgeted tenant improvements and condition-assessment items. | Y2: The offering pairs institutional-grade healthcare net-lease credit with a defensive, unlevered balance sheet. Tenants are investment-grade-equivalent corporate operators on long-dated NNN leases (13.62-yr WALT) with contractual 2.0%-2.5% escalators, in demographically supported submarkets benefiting from outpatient-care migration, an aging cohort, and tight MOB supply. The debt-free structure removes refinance, maturity, cap-cost, and foreclosure exposure and offers a clean basis for 1031 capital seeking certainty of monthly income. The sponsor carries a ~40-year, 153-program operating history, including 57 full-cycle 1031 offerings averaging 6.37% annual cash-on-cash, and the distribution schedule escalates from 5.00% to 6.14% over the projected hold. | Z2: Income is concentrated in three single-tenant assets, with Bristol/United Healthcare alone at ~44% of rent, rendering any single vacancy binary to portfolio cash flow. The master tenant is thinly capitalized - funded by a $500,000 demand promissory note (not cash) from an affiliate, with projected Y1 net income of only ~$2,013 - so a subtenant payment interruption would rapidly exhaust the master tenant's cushion and the trust's limited reserves. The Bristol escalator caps at year 9 and steps flat, flattening growth on the largest asset into the disposition window, where that lease (2037 expiry) leaves only ~1.5 years of residual term at a 2035 exit - a material re-leasing/rollover overhang on the highest-rent asset at the point of valuation. The UNH parent's Fitch outlook turned negative in July 2025, and the Bristol lessee is an operating subsidiary rather than the rated parent. Reserve adequacy is thin post the $221,000 CT transfer-tax draw, and a one-month UNH rent abatement (August 2026) dampens Y1 collections. | AA2: This is a low-beta, income-oriented core net-lease vehicle whose return is almost entirely a function of contractual escalators and terminal value, given the absence of leverage and any value-add component. The 5.00% to 6.14% distribution ramp is mechanically supported by the lease schedule, but the early-year spread between subtenant rent collected and master-lease rent paid is razor-thin, concentrating execution risk in the thinly capitalized master tenant. The debt-free design is genuinely defensive in a higher-for-longer regime, sidestepping the leveraged-net-lease maturity wall and cap-cost repricing, but the same feature suppresses yield - the 5.00% going-in sits below AEI's own operating-program current yield (5.48%) and full-cycle average (6.37%), implying reliance on escalators and exit pricing compression to reach target total return. The dominant underwriting sensitivity is terminal value: with no amortization and a fixed escalator schedule, investor IRR is governed by the year-10 disposition pricing against a portfolio whose largest asset will carry only short residual lease term at exit, while Austin (2038) and Surprise (2042) provide longer-dated support to residual value. Feasibility of the projected distributions is reasonable on a contractual basis; the credible variance is in capital-event timing and exit pricing rather than in-place income. | AB2: 0.05 | AC2: 0.0504 | AD2: 0.0507 | AE2: 0.0535 | AF2: 0.0547 | AG2: 0.0563 | AH2: 0.0576 | AI2: 0.059 | AJ2: 0.0603 | AK2: 0.0614 | AL2: 0.0554 | AM2: Not disclosed | AN2: =IFERROR((AB2 * ((1 - VALUE(SUBSTITUTE(H2, " LTV", ""))) + 0.02)) + (PMT(0.0535/12, 25*12, -VALUE(SUBSTITUTE(H2, " LTV", ""))) * 12) + (0.02/10) + (0.03/10) + 0.02, "N/A") -> 0.076 | AO2: None (debt-free) | AP2: N/A (no debt) | AQ2: N/A (no debt) | AR2: N/A (no debt) | AS2: N/A (no debt) | AT2: N/A - no debt service | AV2: https://drive.google.com/file/d/1UpckdXDq8HJjnUzTg9n_WOvsJA0k1qGf/view?usp=sharing | AX2: 100000 | AY2: =IFERROR(__xludf.DUMMYFUNCTION("IF(ISBLANK(AV2), """", IF(REGEXMATCH(AV2, ""/file/d/""), ""https://lh3.googleusercontent.com/d/"" & REGEXEXTRACT(AV2, ""/d/([a-zA-Z0-9_-]+)""), AV2))"),"https://lh3.googleusercontent.com/d/1UpckdXDq8HJjnUzTg9n_WOvsJA0k1qGf") -> https://lh3.googleusercontent.com/d/1UpckdXDq8HJjnUzTg9n_WOvsJA0k1qGf | AZ2: =IF(AM2="Not Disclosed", AB2 + ((14545 / 100000) * (0.32 / (1 - 0.32))), AM2) -> 0.11844706 | BA2: =if(AM2="Not Disclosed", "Est. Tax-Adjusted Yield⁹", "Tax-Adjusted Yield") -> Est. Tax-Adjusted Yield⁹ | BB2: =if(AW2="", "Offering Documents Available By Request", "Download Offering Documents") -> Offering Documents Available By Request | BC2: aei-healthcare-portfolio-vii-dst | BD2: sponsors/aei-capital-corporation | BE2: property-type/healthcare | BF2: ="Learn More About "&B2 -> Learn More About AEI Capital Corporation | BG2: ="Learn More About "&L2&" Properties" -> Learn More About Healthcare Properties | BH2: {=IFERROR(XLOOKUP($B2, 'Sponsor Connection'!$A:$A, 'Sponsor Connection'!$B:$B), )} -> 1970 | BI2: {=IFERROR(XLOOKUP($B2, 'Sponsor Connection'!$A:$A, 'Sponsor Connection'!$D:$D), )} -> AEI is among the longest-tenured names in the net-lease 1031 space, tracing its lineage to 1970 and to what it describes as one of the earliest securitized fractional-ownership structures. The firm's franchise is built on debt-free, all-cash ownership of single-tenant retail, restaurant and healthcare properties leased to credit-quality operators—a conservative posture that strips refinancing and foreclosure risk out of the capital stack and has carried it through multiple real estate cycles. With decades of completed full-cycle programs behind it, AEI markets stability and longevity over scale or sector breadth, a profile that resonates with risk-averse exchangers prioritizing capital preservation over yield. | BJ2: {=IF($B2="", "", LET(aum, IFERROR(XLOOKUP($B2, 'Sponsor Connection'!$A:$A, 'Sponsor Connection'!$C:$C), ""), IF(OR(aum="", aum=0), "Not Reported", aum)))} -> 1610000000 | BK2: {=IF(ISBLANK($B2), "", LET(val, IFERROR(XLOOKUP($B2, 'Sponsor Connection'!$A:$A, 'Sponsor Connection'!$M:$M), ""), IF(OR(ISBLANK(val), val="", val=0), "Not Reported", val)))} -> 48 | BL2: {=IF(ISBLANK($B2), "", LET(val, IFERROR(XLOOKUP($B2, 'Sponsor Connection'!$A:$A, 'Sponsor Connection'!$N:$N), ""), IF(val="", "Not Reported", val)))} -> 0.067466667 | BM2: {=IF(ISBLANK($B2), "", LET(val, IFERROR(XLOOKUP($B2, 'Sponsor Connection'!$A:$A, 'Sponsor Connection'!$O:$O), ""), IF(val="", "Not Reported", val)))} -> 1.548125 | BN2: {=IF(ISBLANK($B2), "", LET(val, IFERROR(XLOOKUP($B2, 'Sponsor Connection'!$A:$A, 'Sponsor Connection'!$P:$P), ""), IF(val="", "Not Reported", val)))} -> 13.315417 | BO2: {=IF(ISBLANK($B2), "", LET(val, IFERROR(XLOOKUP($B2, 'Sponsor Connection'!$A:$A, 'Sponsor Connection'!$Q:$Q), ""), IF(val="", "Not Reported", val)))} -> 1 | BP2: https://img.logo.dev/aeifunds.com?token=pk_FIVsDKgZTvCedVXXtt2rEg&size=200&retina=true | BQ2: =AL2 -> 0.0554 | BR2: =IFERROR(VLOOKUP(L2, Benchmarks!$A$2:$D$15, 2, FALSE), "Not Analyzed") -> 0.0641 | BS2: =IFERROR(IF(OR(ISBLANK(BQ2), ISBLANK(BR2)), "", IF(ABS(BQ2-BR2)/BQ2 <= 0.1, "Meets Average", IF(BQ2 > BR2, "Above Average", "Below Average"))), "Not Analyzed") -> Below Average | BT2: =iferror((BW2-AB2)/AB2, 0) -> 0.228 | BU2: =IFERROR(VLOOKUP(L2, Benchmarks!$A$2:$D$15, 4, FALSE), "Not Analyzed") -> 0.15430055 | BV2: =IFERROR(IF(OR(ISBLANK(BT2), ISBLANK(BU2)), "", IF(ABS(BT2-BU2)/BT2 <= 0.1, "Meets Average", IF(BT2 > BU2, "Above Average", "Below Average"))), "Not Analyzed") -> Above Average | BW2: =max(AB2:AK2) -> 0.0614 | BX2: =IFERROR(VLOOKUP(L2, Benchmarks!$A$2:$D$15, 3, FALSE), "Not Analyzed") -> 0.07025 | BY2: =IFERROR(IF(OR(ISBLANK(BW2), ISBLANK(BX2)), "", IF(ABS(BW2-BX2)/BW2 <= 0.1, "Meets Average", IF(BW2 > BX2, "Above Average", "Below Average"))), "Not Analyzed") -> Below Average | BZ2: ="Investment: " & A2 & " | Sponsor: " & B2 & " | Structure: " & C2 & " | Status: " & D2 & " | LTV: " & H2 & " | Availability: " & K2 & " | Location: " & N2 & " | Strategy: " & P2 & " | 721 Exchange Exit: " & Q2 & " | Estimated Hold: " & R2 & " | Cap Rate Equivalent: " & AN2 & " | Minimum Investment: " & AX2 -> Investment: AEI Healthcare Portfolio VII DST | Sponsor: AEI Capital Corporation | Structure: Delaware Statutory Trust (DST) | Status: Available | LTV: 0.00% LTV | Availability: 0.508531821782178 | Location: AZ, CT, TX | Strategy: Core | 721 Exchange Exit: Optional | Estimated Hold: 10 years | Cap Rate Equivalent: 0.076 | Minimum Investment: 100000 | CA2: =A2&" ("&H2&")"&CHAR(10)&CHAR(10)&"AEI Healthcare Portfolio VII is a debt-free Delaware Statutory Trust holding three purpose-built, single-tenant outpatient medical office assets across Arizona, Texas, and Connecticut, net-leased to healthcare operators on terms running to 2037-2042. Cont"&"ractual 2.0%-2.5% annual escalators and tenant-reimbursed insurance produce escalating net-lease income with minimal trust-level expense. The all-cash structure carries no refinancing or interest-rate exposure, positioning the offering as a core, income-o"&"riented vehicle underpinned by secular outpatient-care migration and aging demographics."&CHAR(10)&CHAR(10)&">> Download Offering Documents"&CHAR(10)&"https://www.baker1031.com/sponsors/aei-capital-corporation" -> AEI Healthcare Portfolio VII DST (0.00% LTV) AEI Healthcare Portfolio VII is a debt-free Delaware Statutory Trust holding three purpose-built, single-tenant outpatient medical office assets across Arizona, Texas, and Connecticut, net-leased to healthcare operators on terms running to 2037-2042. Contractual 2.0%-2.5% annual escalators and tenant-reimbursed insurance produce escalating net-lease income with minimal trust-level expense. The all-cash structure carries no refinancing or interest-rate exposure, positioning the offering as a core, income-oriented vehicle underpinned by secular outpatient-care migration and aging demographics. >> Download Offering Documents https://www.baker1031.com/sponsors/aei-capital-corporation
A3: Blue Door Property II, DST | B3: SmartStop | C3: Delaware Statutory Trust (DST) | D3: Available | E3: 64766336 | F3: 64766336 | G3: 0 | H3: 0.00% LTV | I3: 41797727 | J3: 46113 | K3: =(I3/F3) -> 0.64536192 | L3: Self-Storage | M3: FL, TX | N3: =IFERROR(__xludf.DUMMYFUNCTION("TEXTJOIN("", "", TRUE, SORT(TRANSPOSE(SPLIT(M3, "", ""))))"),"FL, TX") -> FL, TX | O3: 13.02% | P3: Core-Plus | Q3: Optional | R3: 10 years | S3: Three stabilized self-storage facilities (~301,000 rentable SF; 2,281 storage units and 98 vehicle/RV spaces) held debt-free in a parent/operating DST structure and operated under the SmartStop Self Storage brand: 6707 Narcoossee Road, Orlando FL (97,300 SF, 677 units, 2003 vintage, in the high-growth Lake Nona/Narcoossee corridor), 3701 FM Road 2181, Corinth TX (97,050 SF, 766 units, 2000-2005 vintage, Denton County/DFW), and 7905 Spencer Highway, Pasadena TX (106,618 SF, 838 units plus 81 vehicle spaces, 2003-2007 vintage, Houston/Bay Area). Portfolio occupancy is ~91.2%. The properties are leased to an affiliated master tenant under a 10-year master lease with a base/additional/bonus-rent waterfall, and managed by a SmartStop-affiliated property manager. Thesis is inflation-responsive operating income from necessity-based self-storage in Sun Belt growth markets, with month-to-month rental structure enabling active revenue management and an optional Section 721 rollover into the sponsor's affiliated operating partnership. | T3: The portfolio is operated under the SmartStop Self Storage platform (ultimate parent SmartStop Self Storage REIT, NYSE: SMA), a scaled institutional self-storage owner-operator with established revenue-management systems. Operating control, master-tenant, and property-management functions all sit with SmartStop affiliates, aligning the assets with a national operator's pricing and marketing infrastructure; the same arrangement concentrates execution dependence on a single, vertically affiliated operator rather than diversified third parties. | U3: The Orlando asset anchors the portfolio in the Lake Nona/Narcoossee corridor, among the fastest-growing submarkets in the Sun Belt, with heavy 2023-2024 residential delivery (multiple 250-350 unit multifamily projects and a 156-room hotel) generating new household formation that drives storage demand. The same pipeline, however, includes a 100,000 SF self-storage facility delivered in 2024, an explicit competitive-supply signal in a sector where demand is hyper-local to a roughly three-mile trade area. | V3: Self-storage's month-to-month rental structure permits near-continuous repricing through revenue management, providing inflation pass-through that fixed long-term net leases cannot replicate; the master-lease waterfall channels this upside to investors via Additional Rent and Bonus Rent (80% of gross income above stated breakpoints), so forecast distributions escalate from 4.41% to 5.06% on operating performance rather than contractual escalators. The offset is structurally higher tenant churn and occupancy volatility than credit-tenant net lease. | W3: The portfolio was acquired free and clear with cash, eliminating mortgage, refinancing, maturity, rate-cap, and foreclosure risk, and removing the equal-or-greater-debt replacement requirement for 1031 investors averse to boot-offsetting leverage. The trust agreement nonetheless preserves the ability to incur future financing, so the debt-free position is a current state rather than a permanent covenant. | X3: For cash (non-1031) investors the structure delivers substantial depreciation shelter, with roughly 74-77% of forecast cash flow sheltered and a tax-equivalent yield averaging approximately 6.16% against a 40% assumed effective tax rate. Combined with the bonus-rent participation, this positions the offering as an income vehicle with embedded tax efficiency and modest operating upside rather than a fixed-coupon instrument. | Y3: The offering provides debt-free ownership of a diversified, stabilized self-storage portfolio (three facilities across two high-growth Sun Belt states) operated by a scaled public-REIT platform with institutional revenue-management capability. The month-to-month lease structure permits inflation pass-through, and the master-lease bonus-rent waterfall gives investors direct participation in NOI upside, supporting a distribution ramp from 4.41% to 5.06% over the forecast. Depreciation shelter is meaningful for cash investors (~6.16% average tax-equivalent yield), the capital structure carries no refinancing or maturity exposure, and an optional Section 721 contribution offers a potential tax-deferred exit path into the sponsor's affiliated operating partnership. | Z3: The going-in distribution is low at 4.41%, below comparable net-lease DSTs, and reaching 5.06% by year 10 depends on revenue-management execution and bonus-rent realization rather than contractual escalators. Self-storage is supply-sensitive and demand is hyper-local; the Lake Nona submarket already absorbed a new 100,000 SF facility in 2024, a direct competitive threat to the Orlando asset. Operating dependence is concentrated in newly formed SmartStop affiliates (the property manager was formed July 2024) acting as master tenant, manager, and asset manager, with a thinly capitalized affiliated master tenant and no third-party operating diversification. The 721 exit would deliver OP units in SSGT III's operating partnership, a private, non-traded REIT, not the NYSE-listed SmartStop, so the rollover liquidity is into an illiquid private vehicle dependent on SSGT III's own future liquidity events. The assets are older vintage (2000-2007) than new-construction net-lease product, with a single $1,854,800 reserve covering three aging facilities, and total load is high at 13.02% with a 2.52% acquisition fee and a 2.0% disposition fee further compressing net proceeds. | AA3: This is a debt-free, core-plus self-storage vehicle whose return mechanics differ structurally from net-lease DSTs: distributions track operating NOI through a base/additional/bonus-rent waterfall rather than fixed credit-tenant escalators, so the 4.41% to 5.06% ramp is a function of SmartStop's revenue-management execution and submarket fundamentals, not a contractual obligation. The unlevered structure is defensive against the rate environment but caps return, leaving the investment case resting on self-storage's inflation pass-through, the depreciation shelter (~75% of cash flow; ~6.16% average tax-equivalent yield for cash investors), and the optional 721 rollover. Underwriting feasibility hinges on sustaining and growing ~91% occupancy and street rates across three Sun Belt facilities against visible new supply in Lake Nona. The dominant risk-adjusted question is whether revenue-management upside and bonus rent justify a sub-5% going-in yield and a ~13% load over a 10-year horizon, with terminal value and the form and liquidity of any 721 consideration, private SSGT III OP units, as the principal exit sensitivities. | AB3: 0.0441 | AC3: 0.0451 | AD3: 0.0455 | AE3: 0.0461 | AF3: 0.0464 | AG3: 0.047 | AH3: 0.0481 | AI3: 0.0486 | AJ3: 0.0496 | AK3: 0.0506 | AL3: 0.0471 | AM3: 0.0616 | AN3: =IFERROR((AB3 * ((1 - VALUE(SUBSTITUTE(H3, " LTV", ""))) + 0.02)) + (PMT(0.0535/12, 25*12, -VALUE(SUBSTITUTE(H3, " LTV", ""))) * 12) + (0.02/10) + (0.03/10) + 0.02, "N/A") -> 0.069982 | AO3: None (debt-free) | AP3: N/A (no debt) | AQ3: N/A (no debt) | AR3: N/A (no debt) | AS3: N/A (no debt) | AT3: N/A - no debt service | AU3: 7905 Spencer Highway, Pasadena, TX | AV3: https://drive.google.com/file/d/1-val7swkH1VPNam90f34CrzczJjcQaHO/view?usp=sharing | AX3: 100000 | AY3: =IFERROR(__xludf.DUMMYFUNCTION("IF(ISBLANK(AV3), """", IF(REGEXMATCH(AV3, ""/file/d/""), ""https://lh3.googleusercontent.com/d/"" & REGEXEXTRACT(AV3, ""/d/([a-zA-Z0-9_-]+)""), AV3))"),"https://lh3.googleusercontent.com/d/1-val7swkH1VPNam90f34CrzczJjcQaHO") -> https://lh3.googleusercontent.com/d/1-val7swkH1VPNam90f34CrzczJjcQaHO | AZ3: =IF(AM3="Not Disclosed", AB3 + ((14545 / 100000) * (0.32 / (1 - 0.32))), AM3) -> 0.0616 | BA3: =if(AM3="Not Disclosed", "Est. Tax-Adjusted Yield⁹", "Tax-Adjusted Yield") -> Tax-Adjusted Yield | BB3: =if(AW3="", "Offering Documents Available By Request", "Download Offering Documents") -> Offering Documents Available By Request | BC3: blue-door-property-ii-dst | BD3: sponsors/smartstop | BE3: property-type/self-storage | BF3: ="Learn More About "&B3 -> Learn More About SmartStop | BG3: ="Learn More About "&L3&" Properties" -> Learn More About Self-Storage Properties | BH3: {=IFERROR(XLOOKUP($B3, 'Sponsor Connection'!$A:$A, 'Sponsor Connection'!$B:$B), )} -> 2013 | BI3: {=IFERROR(XLOOKUP($B3, 'Sponsor Connection'!$A:$A, 'Sponsor Connection'!$D:$D), )} -> SmartStop is a self-storage REIT (NYSE: SMA) that completed an $810 million IPO in April 2025 and sponsors self-storage DSTs through its broader platform, with assets in the $7 billion-plus range post-listing. Its pure-play self-storage focus, internal management and combined U.S.-and-Canada footprint give it a clean, single-sector thesis, and the recent public listing adds a transparency and liquidity dimension uncommon among DST sponsors. For exchangers, it offers concentrated exposure to a resilient, low-operating-intensity asset class. | BJ3: {=IF($B3="", "", LET(aum, IFERROR(XLOOKUP($B3, 'Sponsor Connection'!$A:$A, 'Sponsor Connection'!$C:$C), ""), IF(OR(aum="", aum=0), "Not Reported", aum)))} -> 7000000000 | BK3: {=IF(ISBLANK($B3), "", LET(val, IFERROR(XLOOKUP($B3, 'Sponsor Connection'!$A:$A, 'Sponsor Connection'!$M:$M), ""), IF(OR(ISBLANK(val), val="", val=0), "Not Reported", val)))} -> Not Reported | BL3: {=IF(ISBLANK($B3), "", LET(val, IFERROR(XLOOKUP($B3, 'Sponsor Connection'!$A:$A, 'Sponsor Connection'!$N:$N), ""), IF(val="", "Not Reported", val)))} -> No Data | BM3: {=IF(ISBLANK($B3), "", LET(val, IFERROR(XLOOKUP($B3, 'Sponsor Connection'!$A:$A, 'Sponsor Connection'!$O:$O), ""), IF(val="", "Not Reported", val)))} -> No Data | BN3: {=IF(ISBLANK($B3), "", LET(val, IFERROR(XLOOKUP($B3, 'Sponsor Connection'!$A:$A, 'Sponsor Connection'!$P:$P), ""), IF(val="", "Not Reported", val)))} -> No Data | BO3: {=IF(ISBLANK($B3), "", LET(val, IFERROR(XLOOKUP($B3, 'Sponsor Connection'!$A:$A, 'Sponsor Connection'!$Q:$Q), ""), IF(val="", "Not Reported", val)))} -> No Data | BP3: {=IFERROR(XLOOKUP($B3, 'Sponsor Connection'!$A:$A, 'Sponsor Connection'!$L:$L), )} -> https://img.logo.dev/smartstop.com?token=pk_FIVsDKgZTvCedVXXtt2rEg&size=200&retina=true | BQ3: =AL3 -> 0.0471 | BR3: =IFERROR(VLOOKUP(L3, Benchmarks!$A$2:$D$15, 2, FALSE), "Not Analyzed") -> 0.04495 | BS3: =IFERROR(IF(OR(ISBLANK(BQ3), ISBLANK(BR3)), "", IF(ABS(BQ3-BR3)/BQ3 <= 0.1, "Meets Average", IF(BQ3 > BR3, "Above Average", "Below Average"))), "Not Analyzed") -> Meets Average | BT3: =iferror((BW3-AB3)/AB3, 0) -> 0.14739229 | BU3: =IFERROR(VLOOKUP(L3, Benchmarks!$A$2:$D$15, 4, FALSE), "Not Analyzed") -> 0.13869615 | BV3: =IFERROR(IF(OR(ISBLANK(BT3), ISBLANK(BU3)), "", IF(ABS(BT3-BU3)/BT3 <= 0.1, "Meets Average", IF(BT3 > BU3, "Above Average", "Below Average"))), "Not Analyzed") -> Meets Average | BW3: =max(AB3:AK3) -> 0.0506 | BX3: =IFERROR(VLOOKUP(L3, Benchmarks!$A$2:$D$15, 3, FALSE), "Not Analyzed") -> 0.0479 | BY3: =IFERROR(IF(OR(ISBLANK(BW3), ISBLANK(BX3)), "", IF(ABS(BW3-BX3)/BW3 <= 0.1, "Meets Average", IF(BW3 > BX3, "Above Average", "Below Average"))), "Not Analyzed") -> Meets Average | BZ3: ="Investment: " & A3 & " | Sponsor: " & B3 & " | Structure: " & C3 & " | Status: " & D3 & " | LTV: " & H3 & " | Availability: " & K3 & " | Location: " & N3 & " | Strategy: " & P3 & " | 721 Exchange Exit: " & Q3 & " | Estimated Hold: " & R3 & " | Cap Rate Equivalent: " & AN3 & " | Minimum Investment: " & AX3 -> Investment: Blue Door Property II, DST | Sponsor: SmartStop | Structure: Delaware Statutory Trust (DST) | Status: Available | LTV: 0.00% LTV | Availability: 0.645361920736106 | Location: FL, TX | Strategy: Core-Plus | 721 Exchange Exit: Optional | Estimated Hold: 10 years | Cap Rate Equivalent: 0.069982 | Minimum Investment: 100000 | CA3: =A3&" ("&H3&")"&CHAR(10)&CHAR(10)&"Blue Door Property II is a debt-free DST holding three stabilized SmartStop-branded self-storage facilities (~301,000 SF; 2,281 units) in the Orlando, DFW, and Houston Sun Belt growth corridors at ~91.2% occupancy. The assets are operated under a 10-year "&"affiliated master lease with a base/additional/bonus-rent waterfall and active, month-to-month revenue management. The thesis targets inflation-responsive operating income from necessity-based storage, with an optional Section 721 rollover into the sponso"&"r's affiliated operating partnership."&CHAR(10)&CHAR(10)&">> Download Offering Documents"&CHAR(10)&"https://www.baker1031.com/sponsors/smartstop" -> Blue Door Property II, DST (0.00% LTV) Blue Door Property II is a debt-free DST holding three stabilized SmartStop-branded self-storage facilities (~301,000 SF; 2,281 units) in the Orlando, DFW, and Houston Sun Belt growth corridors at ~91.2% occupancy. The assets are operated under a 10-year affiliated master lease with a base/additional/bonus-rent waterfall and active, month-to-month revenue management. The thesis targets inflation-responsive operating income from necessity-based storage, with an optional Section 721 rollover into the sponsor's affiliated operating partnership. >> Download Offering Documents https://www.baker1031.com/sponsors/smartstop
A4: Blue Door Property III, DST | B4: SmartStop | C4: Delaware Statutory Trust (DST) | D4: Available | E4: 52636335 | F4: 28444976 | G4: 24191359 | H4: 45.96% LTV | I4: 28444976 | J4: 45974 | K4: =(I4/F4) -> 1 | L4: Self-Storage | M4: AZ, FL, TX | N4: =IFERROR(__xludf.DUMMYFUNCTION("TEXTJOIN("", "", TRUE, SORT(TRANSPOSE(SPLIT(M4, "", ""))))"),"AZ, FL, TX") -> AZ, FL, TX | O4: 15.19% | P4: Core-Plus | Q4: Optional | R4: 7 years | S4: Three self-storage facilities (~1,927 storage units, 24 modular outdoor units, 12 vehicle spaces) held in a parent/operating DST structure, financed at 45.96% LTV and operated under the SmartStop Self Storage brand: 4860 North 83rd Avenue, Phoenix AZ (711 units, ~82,435 SF), 460 Florida Central Parkway, Longwood FL (542 units, 12 vehicle spaces), and 8110 S. Cockrell Hill Road, Dallas TX (674 units plus 24 modular outdoor units). Portfolio occupancy is ~90% (~92% at Phoenix). Each property carries a separate fixed-rate interest-only mortgage from a SmartStop-affiliated lender (aggregate $24,191,359), and each is leased to a state-specific affiliated master tenant under its own master lease with a base/additional/bonus-rent waterfall, managed by a SmartStop-affiliated property manager. Thesis is leveraged, inflation-responsive operating income from necessity-based self-storage across three Sun Belt metros, with active revenue management and an optional Section 721 rollover into the sponsor's affiliated operating partnership ahead of the November 2032 loan maturity. | T4: This is a leveraged structure (45.96% LTV) financed with three separate fixed-rate mortgages at 5.00%, interest-only for the full seven-year term from SMST Lender, LLC, a SmartStop affiliate, maturing November 13, 2032. Interest-only with no amortization maximizes current distributions but builds no principal equity, so the entire $24.19M balloons at maturity; the seven-year hold is explicitly structured to dispose of the assets before that date, and the affiliated-lender, related-party terms warrant independent scrutiny. | U4: The portfolio is operated under the SmartStop Self Storage platform (ultimate parent SmartStop Self Storage REIT, NYSE: SMA), with state-specific affiliated master tenants and a SmartStop-affiliated property manager. This aligns the assets with a scaled operator's revenue-management and marketing infrastructure, while concentrating master-tenant, management, lending, and 721-counterparty roles within a single sponsor family rather than diversified third parties. | V4: Geographic diversification spans three independent Sun Belt storage trade areas, Phoenix, the Orlando/Longwood corridor, and Dallas, at roughly 90% occupancy (about 92% at Phoenix). Spreading income across three metros with distinct supply-demand dynamics reduces the single-market concentration risk inherent to a one-submarket storage deal, though self-storage demand remains hyper-local within each. | W4: At a 5.00% fixed borrowing cost against the portfolio's going-in NOI yield, the moderate leverage modestly amplifies investor cash-on-cash relative to an all-equity structure, and the interest-only feature removes amortization drag to support current distributions. The trade-off is that no equity is built through paydown, leaving exit value entirely dependent on NOI growth and the terminal value against a fixed principal balloon. | X4: The combination of leverage (interest deductibility) and depreciation produces high tax shelter, roughly 89-92% of cash flow sheltered in the early years, yielding an average tax-equivalent yield near 7.08% for non-1031 cash investors at a 40% assumed effective rate. The after-tax profile is materially stronger than the ~4.28% pre-tax cash-on-cash, positioning the offering as a tax-efficient leveraged income vehicle. | Y4: The offering provides a geographically diversified self-storage portfolio across three Sun Belt metros operated by the SmartStop public-REIT platform, with institutional revenue-management capability and month-to-month leases that permit inflation pass-through and bonus-rent upside. Financing is fixed-rate (5.00%) and interest-only, locking coupon cost and maximizing current distributions, and Year 1 debt-service coverage is healthy at 1.81x. Depreciation and interest shelter are substantial (~7.08% average tax-equivalent yield for cash investors), and an optional Section 721 contribution offers a potential tax-deferred exit into the sponsor's affiliated operating partnership. | Z4: The financing is interest-only with a hard seven-year balloon (November 2032) and no amortization, so the full $24.19M principal must be refinanced or repaid at exit; any delay forces extension at floating SOFR plus 1.50%, surrendering the 5.00% fixed coupon precisely at the maturity wall. Financing, master tenants, property management, and the 721 counterparty are all SmartStop affiliates, creating pervasive conflicts with no arm's-length check on loan or lease terms, and each master tenant is capitalized only by a small demand note from the affiliated operating partnership ($441,000 Phoenix, $322,000 Dallas, among them), reducible by retained earnings. Going-in cash yield is low at 4.00%, reaching only 4.52% by year 7 and dependent on revenue-management execution and bonus rent, against a high 15.19% load plus a 2.0% disposition fee. The 721 consideration would be units in SS Growth Operating Partnership III, a private, non-traded REIT, not the listed SmartStop, and the appraised value ($45.3M) sits only marginally above purchase price ($44.24M), leaving thin day-one equity cushion against 45.96% leverage (debt-to-appraised-value roughly 53%) in a supply-sensitive sector. | AA4: Blue Door III is a moderately leveraged, core-plus self-storage vehicle that contrasts sharply with its debt-free sibling: the 45.96% LTV fixed-rate interest-only financing amplifies both cash-on-cash and tax shelter while imposing a defined seven-year refinancing-or-sale imperative tied to the November 2032 maturity. The investment case rests on SmartStop lifting NOI across three Sun Belt facilities through revenue management, with the interest-only structure front-loading distributions but building no principal equity, so terminal value is wholly a function of NOI growth and exit pricing against a balloon. Pervasive affiliation across lender, master tenants, manager, and 721 counterparty concentrates both operational alignment and conflict risk in one sponsor family, and the thin day-one equity cushion leaves limited margin if storage fundamentals soften. The after-tax profile is the strongest feature, roughly 89-92% early-year shelter and a ~7.08% tax-equivalent yield for cash investors, but the 4.00% pre-tax going-in yield, 15.19% load, and floating-rate extension risk make the offering most coherent for tax-sensitive investors comfortable with leverage and a defined exit window rather than those prioritizing capital preservation. | AB4: 0.04 | AC4: 0.0425 | AD4: 0.0427 | AE4: 0.0428 | AF4: 0.0431 | AG4: 0.0432 | AH4: 0.0452 | AI4: Sold | AJ4: Sold | AK4: Sold | AL4: 0.0428 | AM4: 0.0708 | AN4: =IFERROR((AB4 * ((1 - VALUE(SUBSTITUTE(H4, " LTV", ""))) + 0.02)) + (PMT(0.0535/12, 25*12, -VALUE(SUBSTITUTE(H4, " LTV", ""))) * 12) + (0.02/10) + (0.03/10) + 0.02, "N/A") -> 0.080791891 | AO4: SMST Lender, LLC | AP4: 5.00% (Fixed) | AQ4: 7 years | AR4: 7 years | AS4: N/A (interest-only) | AT4: 1.81x | AU4: 4860 North 83rd Avenue, Phoenix, AZ | AV4: https://lh3.googleusercontent.com/d/1GCvzEMexmpTgjlyyGJUhAnO2MFsnLqaV | AX4: 100000 | AY4: =IFERROR(__xludf.DUMMYFUNCTION("IF(ISBLANK(AV4), """", IF(REGEXMATCH(AV4, ""/file/d/""), ""https://lh3.googleusercontent.com/d/"" & REGEXEXTRACT(AV4, ""/d/([a-zA-Z0-9_-]+)""), AV4))"),"https://lh3.googleusercontent.com/d/1GCvzEMexmpTgjlyyGJUhAnO2MFsnLqaV") -> https://lh3.googleusercontent.com/d/1GCvzEMexmpTgjlyyGJUhAnO2MFsnLqaV | AZ4: =IF(AM4="Not Disclosed", AB4 + ((14545 / 100000) * (0.32 / (1 - 0.32))), AM4) -> 0.0708 | BA4: =if(AM4="Not Disclosed", "Est. Tax-Adjusted Yield⁹", "Tax-Adjusted Yield") -> Tax-Adjusted Yield | BB4: =if(AW4="", "Offering Documents Available By Request", "Download Offering Documents") -> Offering Documents Available By Request | BC4: blue-door-property-iii-dst | BD4: sponsors/smartstop | BE4: property-type/self-storage | BF4: ="Learn More About "&B4 -> Learn More About SmartStop | BG4: ="Learn More About "&L4&" Properties" -> Learn More About Self-Storage Properties | BH4: {=IFERROR(XLOOKUP($B4, 'Sponsor Connection'!$A:$A, 'Sponsor Connection'!$B:$B), )} -> 2013 | BI4: {=IFERROR(XLOOKUP($B4, 'Sponsor Connection'!$A:$A, 'Sponsor Connection'!$D:$D), )} -> SmartStop is a self-storage REIT (NYSE: SMA) that completed an $810 million IPO in April 2025 and sponsors self-storage DSTs through its broader platform, with assets in the $7 billion-plus range post-listing. Its pure-play self-storage focus, internal management and combined U.S.-and-Canada footprint give it a clean, single-sector thesis, and the recent public listing adds a transparency and liquidity dimension uncommon among DST sponsors. For exchangers, it offers concentrated exposure to a resilient, low-operating-intensity asset class. | BJ4: {=IF($B4="", "", LET(aum, IFERROR(XLOOKUP($B4, 'Sponsor Connection'!$A:$A, 'Sponsor Connection'!$C:$C), ""), IF(OR(aum="", aum=0), "Not Reported", aum)))} -> 7000000000 | BK4: {=IF(ISBLANK($B4), "", LET(val, IFERROR(XLOOKUP($B4, 'Sponsor Connection'!$A:$A, 'Sponsor Connection'!$M:$M), ""), IF(OR(ISBLANK(val), val="", val=0), "Not Reported", val)))} -> Not Reported | BL4: {=IF(ISBLANK($B4), "", LET(val, IFERROR(XLOOKUP($B4, 'Sponsor Connection'!$A:$A, 'Sponsor Connection'!$N:$N), ""), IF(val="", "Not Reported", val)))} -> No Data | BM4: {=IF(ISBLANK($B4), "", LET(val, IFERROR(XLOOKUP($B4, 'Sponsor Connection'!$A:$A, 'Sponsor Connection'!$O:$O), ""), IF(val="", "Not Reported", val)))} -> No Data | BN4: {=IF(ISBLANK($B4), "", LET(val, IFERROR(XLOOKUP($B4, 'Sponsor Connection'!$A:$A, 'Sponsor Connection'!$P:$P), ""), IF(val="", "Not Reported", val)))} -> No Data | BO4: {=IF(ISBLANK($B4), "", LET(val, IFERROR(XLOOKUP($B4, 'Sponsor Connection'!$A:$A, 'Sponsor Connection'!$Q:$Q), ""), IF(val="", "Not Reported", val)))} -> No Data | BP4: {=IFERROR(XLOOKUP($B4, 'Sponsor Connection'!$A:$A, 'Sponsor Connection'!$L:$L), )} -> https://img.logo.dev/smartstop.com?token=pk_FIVsDKgZTvCedVXXtt2rEg&size=200&retina=true | BQ4: =AL4 -> 0.0428 | BR4: =IFERROR(VLOOKUP(L4, Benchmarks!$A$2:$D$15, 2, FALSE), "Not Analyzed") -> 0.04495 | BS4: =IFERROR(IF(OR(ISBLANK(BQ4), ISBLANK(BR4)), "", IF(ABS(BQ4-BR4)/BQ4 <= 0.1, "Meets Average", IF(BQ4 > BR4, "Above Average", "Below Average"))), "Not Analyzed") -> Meets Average | BT4: =iferror((BW4-AB4)/AB4, 0) -> 0.13 | BU4: =IFERROR(VLOOKUP(L4, Benchmarks!$A$2:$D$15, 4, FALSE), "Not Analyzed") -> 0.13869615 | BV4: =IFERROR(IF(OR(ISBLANK(BT4), ISBLANK(BU4)), "", IF(ABS(BT4-BU4)/BT4 <= 0.1, "Meets Average", IF(BT4 > BU4, "Above Average", "Below Average"))), "Not Analyzed") -> Meets Average | BW4: =max(AB4:AK4) -> 0.0452 | BX4: =IFERROR(VLOOKUP(L4, Benchmarks!$A$2:$D$15, 3, FALSE), "Not Analyzed") -> 0.0479 | BY4: =IFERROR(IF(OR(ISBLANK(BW4), ISBLANK(BX4)), "", IF(ABS(BW4-BX4)/BW4 <= 0.1, "Meets Average", IF(BW4 > BX4, "Above Average", "Below Average"))), "Not Analyzed") -> Meets Average | BZ4: ="Investment: " & A4 & " | Sponsor: " & B4 & " | Structure: " & C4 & " | Status: " & D4 & " | LTV: " & H4 & " | Availability: " & K4 & " | Location: " & N4 & " | Strategy: " & P4 & " | 721 Exchange Exit: " & Q4 & " | Estimated Hold: " & R4 & " | Cap Rate Equivalent: " & AN4 & " | Minimum Investment: " & AX4 -> Investment: Blue Door Property III, DST | Sponsor: SmartStop | Structure: Delaware Statutory Trust (DST) | Status: Available | LTV: 45.96% LTV | Availability: 1 | Location: AZ, FL, TX | Strategy: Core-Plus | 721 Exchange Exit: Optional | Estimated Hold: 7 years | Cap Rate Equivalent: 0.0807918912165384 | Minimum Investment: 100000 | CA4: =A4&" ("&H4&")"&CHAR(10)&CHAR(10)&"Blue Door Property III is a leveraged DST holding three SmartStop-branded self-storage facilities (~1,927 units) across Phoenix, Longwood, and Dallas at ~90% occupancy, financed at 45.96% LTV on separate fixed-rate, interest-only mortgages aggregating $24"&".2M. Each asset is leased to a state-specific affiliated master tenant under a base/additional/bonus-rent waterfall with active revenue management. The thesis targets leveraged, inflation-responsive storage income with an optional Section 721 rollover ahe"&"ad of the November 2032 loan maturity."&CHAR(10)&CHAR(10)&">> Download Offering Documents"&CHAR(10)&"https://www.baker1031.com/sponsors/smartstop" -> Blue Door Property III, DST (45.96% LTV) Blue Door Property III is a leveraged DST holding three SmartStop-branded self-storage facilities (~1,927 units) across Phoenix, Longwood, and Dallas at ~90% occupancy, financed at 45.96% LTV on separate fixed-rate, interest-only mortgages aggregating $24.2M. Each asset is leased to a state-specific affiliated master tenant under a base/additional/bonus-rent waterfall with active revenue management. The thesis targets leveraged, inflation-responsive storage income with an optional Section 721 rollover ahead of the November 2032 loan maturity. >> Download Offering Documents https://www.baker1031.com/sponsors/smartstop
A5: Blue Owl Real Estate Exchange V DST | B5: Blue Owl | C5: Delaware Statutory Trust (DST) | D5: Coming Soon / Under Review | E5: 269491892 | F5: 269491892 | G5: 0 | H5: 0.00% LTV | I5: 269491892 | J5: 46028 | K5: =(I5/F5) -> 1 | L5: Industrial | M5: KY, OH, MI | N5: =IFERROR(__xludf.DUMMYFUNCTION("TEXTJOIN("", "", TRUE, SORT(TRANSPOSE(SPLIT(M5, "", ""))))"),"KY, MI, OH") -> KY, MI, OH | O5: 7.50% | P5: Core | Q5: Mandatory | R5: 2 years | S5: Three single-tenant net-leased industrial manufacturing properties held debt-free in a parent/operating DST structure: 111 Cosma Drive, Bowling Green KY (~1,351,200 SF on ~134 acres), 100% leased to Bowling Green Metalforming LLC, a wholly-owned subsidiary of Magna International Inc.; and two American Rheinmetall (Loc Performance Products) facilities, 1115 South Wayne Street, Saint Marys OH (~701,000 SF, 1939-1973 vintage) and 13505 North Haggerty Road, Plymouth MI (~289,000 SF, 2002), each leased to a subsidiary of Rheinmetall AG. Both tenant leases carry ~20-year base terms, with escalators of 1.25% per annum (Magna) and 2.0% per annum (American Rheinmetall). The Magna site includes a ground-lease and industrial-revenue-bond structure providing tax abatement. The properties are owned free and clear, with the trust agreements prohibiting permanent financing, and the master lease is guaranteed by Blue Owl's Operating Partnership subject to a net-worth standard. Thesis is durable, long-duration credit-tenant net-lease income with an optional Section 721 rollover into the non-listed, perpetual-life Blue Owl Real Estate Net Lease Trust. | T5: The portfolio is leased to subsidiaries of two substantial industrial credits: Bowling Green Metalforming, a wholly-owned unit of Magna International, a publicly traded global Tier-1 automotive supplier, and Loc Performance/American Rheinmetall, a subsidiary of Rheinmetall AG, a German defense and industrial group benefiting from the European defense-spending expansion. The Rheinmetall-linked defense exposure is a differentiated, counter-cyclical demand driver atypical of net-lease portfolios, though both leases sit with operating subsidiaries rather than the rated parents. | U5: Both the Magna and American Rheinmetall properties carry approximately 20-year base lease terms, producing an exceptionally long weighted-average lease term that underpins durable contractual income and supports the perpetual-life UPREIT thesis. Escalators differ materially, 2.0% per annum for American Rheinmetall versus a below-market 1.25% per annum for Magna, the latter eroding real income over the multi-decade term. | V5: The portfolio is owned free and clear, and the trust agreements affirmatively prohibit the trustee from placing permanent financing, eliminating refinancing, maturity, and interest-rate risk entirely and removing the equal-or-greater-debt replacement requirement for 1031 investors. The structural cost is the absence of positive leverage, which caps levered return and is the primary reason the going-in distribution sits in the high-4% range. | W5: The FMV Option permits Blue Owl's Operating Partnership, at its sole discretion, to acquire investor interests for OP units in the non-listed, perpetual-life Blue Owl Real Estate Net Lease Trust after a two-year hold, offering a potential tax-deferred path into a large, diversified net-lease REIT platform. The exchange is into a non-traded, illiquid vehicle whose NAV, redemption terms, and exercise timing are sponsor-controlled, ceding investor control and price transparency. | X5: The assets are large, special-purpose manufacturing facilities purpose-built for their incumbents, the Magna plant alone spanning ~1.35M SF on 134 acres, which makes them mission-critical to tenant operations and raises renewal probability, but also concentrates re-leasing and repurposing risk given limited alternative-use demand if a tenant vacates. The AR Ohio asset is of 1939-1973 vintage, and the Magna site carries ground-lease and industrial-revenue-bond complexity tied to its tax abatement. | Y5: The offering provides a long-duration (~20-year WALT) single-tenant net-lease industrial portfolio leased to subsidiaries of two substantial industrial credits, Magna International and Rheinmetall AG, with the defense-linked Rheinmetall exposure adding a differentiated, counter-cyclical demand tailwind. The structure is debt-free with leverage contractually prohibited, removing all refinancing and maturity risk, and the master lease is guaranteed by Blue Owl's Operating Partnership subject to a net-worth covenant. Distributions begin at 4.77% and step up to 6.01% over the 20-year forecast, and the optional Section 721 FMV Option offers a tax-deferred path into the large, diversified, perpetual-life Blue Owl net-lease REIT. | Z5: The properties are large, special-purpose manufacturing facilities with limited alternative-use demand and elevated re-leasing cost if a tenant vacates, and the AR Ohio asset is of 1939-1973 vintage. Both leases are with operating subsidiaries (Bowling Green Metalforming, Loc Performance) rather than the rated parents, and the only contractual credit backstop is Blue Owl's own Operating Partnership guaranty subject to a net-worth standard, concentrating credit support within the sponsor family. The Magna escalator is a below-market 1.25% per annum, eroding real income across a 20-year term, and the Magna site's ground-lease/industrial-revenue-bond structure adds title and tax-abatement complexity. The 721 consideration would be units in the non-listed, perpetual-life Blue Owl REIT, an illiquid vehicle with sponsor-controlled NAV and redemption gates, exercisable only at the Operating Partnership's discretion. Going-in cash yield is modest at 4.77% against a 7.50% upfront load plus ongoing servicing and management fees and a disposition fee. | AA5: Blue Owl V is a debt-free, long-duration credit-tenant net-lease industrial vehicle engineered as a feeder into Blue Owl's perpetual-life net-lease REIT via an optional Section 721 UPREIT. Return is almost entirely contractual and front-loaded by 20-year leases with modest 1.25%-2.0% escalators, so the investment is fundamentally an income-and-tax-deferral play rather than a total-return or appreciation strategy, consistent with its stated capital-preservation objective. The two credits are substantial but exposure runs through operating subsidiaries backed only by the sponsor's Operating Partnership guaranty, and the assets' special-purpose nature concentrates risk in tenant retention over a multi-decade horizon. The defining feature is the perpetual UPREIT optionality: rather than a defined sale, the likely path is conversion into non-listed Blue Owl REIT OP units, moving investors from a discrete, transparent net-lease portfolio into a sponsor-managed, illiquid NAV REIT, attractive for tax-deferral continuity and diversification but ceding control, liquidity, and valuation transparency. The 4.77% going-in distribution is well-supported by in-place contractual rent; the principal sensitivities are long-horizon tenant retention at special-purpose assets and the terms and timing of the eventual 721 conversion. | AB5: 0.0477 | AC5: 0.0477 | AD5: 0.0477 | AE5: 0.0477 | AF5: 0.0477 | AG5: 0.0515 | AH5: 0.0515 | AI5: 0.0515 | AJ5: 0.0515 | AK5: 0.0515 | AL5: 0.0496 | AM5: Not disclosed | AN5: =IFERROR((AB5 * ((1 - VALUE(SUBSTITUTE(H5, " LTV", ""))) + 0.02)) + (PMT(0.0535/12, 25*12, -VALUE(SUBSTITUTE(H5, " LTV", ""))) * 12) + (0.02/10) + (0.03/10) + 0.02, "N/A") -> 0.073654 | AO5: None (debt-free) | AP5: N/A (no debt) | AQ5: N/A (no debt) | AR5: N/A (no debt) | AS5: N/A (no debt) | AT5: N/A - no debt service | AU5: 111 Cosma Drive, Bowling Green, KY | AV5: https://drive.google.com/file/d/1SYLj4lsZa73K392bDZMcdABsto2FWap9/view?usp=sharing | AX5: 100000 | AY5: =IFERROR(__xludf.DUMMYFUNCTION("IF(ISBLANK(AV5), """", IF(REGEXMATCH(AV5, ""/file/d/""), ""https://lh3.googleusercontent.com/d/"" & REGEXEXTRACT(AV5, ""/d/([a-zA-Z0-9_-]+)""), AV5))"),"https://lh3.googleusercontent.com/d/1SYLj4lsZa73K392bDZMcdABsto2FWap9") -> https://lh3.googleusercontent.com/d/1SYLj4lsZa73K392bDZMcdABsto2FWap9 | AZ5: =IF(AM5="Not Disclosed", AB5 + ((14545 / 100000) * (0.32 / (1 - 0.32))), AM5) -> 0.11614706 | BA5: =if(AM5="Not Disclosed", "Est. Tax-Adjusted Yield⁹", "Tax-Adjusted Yield") -> Est. Tax-Adjusted Yield⁹ | BB5: =if(AW5="", "Offering Documents Available By Request", "Download Offering Documents") -> Offering Documents Available By Request | BC5: blue-owl-real-estate-exchange-v-dst | BD5: sponsors/blue-owl | BE5: property-type/industrial | BF5: ="Learn More About "&B5 -> Learn More About Blue Owl | BG5: ="Learn More About "&L5&" Properties" -> Learn More About Industrial Properties | BH5: {=IFERROR(XLOOKUP($B5, 'Sponsor Connection'!$A:$A, 'Sponsor Connection'!$B:$B), )} -> 2009 | BI5: {=IFERROR(XLOOKUP($B5, 'Sponsor Connection'!$A:$A, 'Sponsor Connection'!$D:$D), )} -> Blue Owl Capital is a roughly $273 billion alternatives manager whose net-lease pedigree—anchored by the Oak Street platform it absorbed—feeds its DST/1031 vehicle, Blue Owl Real Estate Exchange (OREX). The strategy is purpose-built around triple-net, sale-leaseback assets leased to creditworthy corporate tenants, a cash-flow-stable profile well suited to exchange investors seeking predictability. With a permanent-capital orientation and a diversified credit-and-real-assets platform behind it, OREX brings institutional sourcing to a niche that rewards tenant credit discipline. | BJ5: {=IF($B5="", "", LET(aum, IFERROR(XLOOKUP($B5, 'Sponsor Connection'!$A:$A, 'Sponsor Connection'!$C:$C), ""), IF(OR(aum="", aum=0), "Not Reported", aum)))} -> 273000000000 | BK5: {=IF(ISBLANK($B5), "", LET(val, IFERROR(XLOOKUP($B5, 'Sponsor Connection'!$A:$A, 'Sponsor Connection'!$M:$M), ""), IF(OR(ISBLANK(val), val="", val=0), "Not Reported", val)))} -> Not Reported | BL5: {=IF(ISBLANK($B5), "", LET(val, IFERROR(XLOOKUP($B5, 'Sponsor Connection'!$A:$A, 'Sponsor Connection'!$N:$N), ""), IF(val="", "Not Reported", val)))} -> No Data | BM5: {=IF(ISBLANK($B5), "", LET(val, IFERROR(XLOOKUP($B5, 'Sponsor Connection'!$A:$A, 'Sponsor Connection'!$O:$O), ""), IF(val="", "Not Reported", val)))} -> No Data | BN5: {=IF(ISBLANK($B5), "", LET(val, IFERROR(XLOOKUP($B5, 'Sponsor Connection'!$A:$A, 'Sponsor Connection'!$P:$P), ""), IF(val="", "Not Reported", val)))} -> No Data | BO5: {=IF(ISBLANK($B5), "", LET(val, IFERROR(XLOOKUP($B5, 'Sponsor Connection'!$A:$A, 'Sponsor Connection'!$Q:$Q), ""), IF(val="", "Not Reported", val)))} -> No Data | BP5: {=IFERROR(XLOOKUP($B5, 'Sponsor Connection'!$A:$A, 'Sponsor Connection'!$L:$L), )} -> https://img.logo.dev/blueowl.com?token=pk_FIVsDKgZTvCedVXXtt2rEg&size=200&retina=true | BQ5: =AL5 -> 0.0496 | BR5: =IFERROR(VLOOKUP(L5, Benchmarks!$A$2:$D$15, 2, FALSE), "Not Analyzed") -> 0 | BS5: =IFERROR(IF(OR(ISBLANK(BQ5), ISBLANK(BR5)), "", IF(ABS(BQ5-BR5)/BQ5 <= 0.1, "Meets Average", IF(BQ5 > BR5, "Above Average", "Below Average"))), "Not Analyzed") -> Above Average | BT5: =iferror((BW5-AB5)/AB5, 0) -> 0.07966457 | BU5: =IFERROR(VLOOKUP(L5, Benchmarks!$A$2:$D$15, 4, FALSE), "Not Analyzed") -> 0.14414694 | BV5: =IFERROR(IF(OR(ISBLANK(BT5), ISBLANK(BU5)), "", IF(ABS(BT5-BU5)/BT5 <= 0.1, "Meets Average", IF(BT5 > BU5, "Above Average", "Below Average"))), "Not Analyzed") -> Below Average | BW5: =max(AB5:AK5) -> 0.0515 | BX5: =IFERROR(VLOOKUP(L5, Benchmarks!$A$2:$D$15, 3, FALSE), "Not Analyzed") -> 0.05854 | BY5: =IFERROR(IF(OR(ISBLANK(BW5), ISBLANK(BX5)), "", IF(ABS(BW5-BX5)/BW5 <= 0.1, "Meets Average", IF(BW5 > BX5, "Above Average", "Below Average"))), "Not Analyzed") -> Below Average | BZ5: ="Investment: " & A5 & " | Sponsor: " & B5 & " | Structure: " & C5 & " | Status: " & D5 & " | LTV: " & H5 & " | Availability: " & K5 & " | Location: " & N5 & " | Strategy: " & P5 & " | 721 Exchange Exit: " & Q5 & " | Estimated Hold: " & R5 & " | Cap Rate Equivalent: " & AN5 & " | Minimum Investment: " & AX5 -> Investment: Blue Owl Real Estate Exchange V DST | Sponsor: Blue Owl | Structure: Delaware Statutory Trust (DST) | Status: Coming Soon / Under Review | LTV: 0.00% LTV | Availability: 1 | Location: KY, MI, OH | Strategy: Core | 721 Exchange Exit: Mandatory | Estimated Hold: 2 years | Cap Rate Equivalent: 0.073654 | Minimum Investment: 100000 | CA5: =A5&" ("&H5&")"&CHAR(10)&CHAR(10)&"Blue Owl Real Estate Exchange V is a debt-free DST holding three single-tenant net-leased industrial manufacturing properties leased to subsidiaries of Magna International and Rheinmetall AG on ~20-year base terms. The Bowling Green Metalforming site carr"&"ies a ground-lease and industrial-revenue-bond structure providing tax abatement, and the trust agreements prohibit permanent financing. The thesis is durable, long-duration credit-tenant net-lease income with an optional Section 721 rollover into the per"&"petual-life Blue Owl Real Estate Net Lease Trust."&CHAR(10)&CHAR(10)&">> Download Offering Documents"&CHAR(10)&"https://www.baker1031.com/sponsors/blue-owl" -> Blue Owl Real Estate Exchange V DST (0.00% LTV) Blue Owl Real Estate Exchange V is a debt-free DST holding three single-tenant net-leased industrial manufacturing properties leased to subsidiaries of Magna International and Rheinmetall AG on ~20-year base terms. The Bowling Green Metalforming site carries a ground-lease and industrial-revenue-bond structure providing tax abatement, and the trust agreements prohibit permanent financing. The thesis is durable, long-duration credit-tenant net-lease income with an optional Section 721 rollover into the perpetual-life Blue Owl Real Estate Net Lease Trust. >> Download Offering Documents https://www.baker1031.com/sponsors/blue-owl
